Workbook

Sheet Summary
A1: Country | B1: ISO | C1: Region | D1: OECD | E1: above_middle_countries | F1: AnnexI_countries | G1: AnnexII_countries | H1: exclude_LDC_SIDS_countries | I1: high_HDI_countries | J1: exclude_vulnerable_countries | K1: high_income | L1: vulnerability_score | M1: X1850_2024 | N1: X1990_2024 | O1: GHG_avg | P1: GHG_2022 | Q1: population_2022 | R1: GHG_historical_pc | S1: GHG_pc_2022 | T1: GNI_avg | U1: GNI_debt_avg | V1: GNI_PPP_avg | W1: GNI_pc_avg | X1: GNI_PPP_pc_avg | Y1: GAIN_CR | Z1: EIB_PR | AA1: EIB_CR | AB1: UN Index
A2: United States | B2: USA | C2: Northern America | D2: 1 | E2: 1 | F2: =IF(G2=1, 1, 0) -> 1 | G2: 1 | H2: 1 | I2: 1 | J2: 1 | K2: 1 | L2: 67.683008 | M2: {=INDEX('cumulative-co-emissions1850'!$D$1:$D$260000,MATCH(1, ('cumulative-co-emissions1850'!$C$1:$C$260000=2024)*('cumulative-co-emissions1850'!$B$1:$B$260000=Summary!$B2), 0)) - IFERROR(INDEX('cumulative-co-emissions1850'!$D$1:$D$260000,MATCH(1, ('cumulative-co-emissions1850'!$C$1:$C$260000=1850)*('cumulative-co-emissions1850'!$B$1:$B$260000=Summary!$B2), 0)), 0)} -> 434676575260 | N2: {=INDEX('cumulative-co-emissions1850'!$D$1:$D$260000,MATCH(1, ('cumulative-co-emissions1850'!$C$1:$C$260000=2024)*('cumulative-co-emissions1850'!$B$1:$B$260000=Summary!$B2), 0)) - IFERROR(INDEX('cumulative-co-emissions1850'!$D$1:$D$260000,MATCH(1, ('cumulative-co-emissions1850'!$C$1:$C$260000=1990)*('cumulative-co-emissions1850'!$B$1:$B$260000=Summary!$B2), 0)), 0)} -> 187363820000 | O2: 406147831 | P2: 5628776.1 | Q2: 333000000 | R2: 1835.6521 | S2: 16.903232 | T2: 22100000000000 | U2: 22100000000000 | V2: 22300000000000 | W2: 66886.667 | X2: 67560 | Y2: =VLOOKUP(B2,gain!$A$2:$AE$193, 31) -> 66.451414 | Z2: =IFERROR(VLOOKUP(B2,EIB!$B$2:$F$177, 2, FALSE), 0.1) -> 0.4 | AA2: =IFERROR(VLOOKUP(B2,EIB!$B$2:$F$177, 4, FALSE), 0) -> 0.1 | AB2: =VLOOKUP(B2,'UN Multilaterism Index'!$B$2:$C$194, 2,FALSE) -> 15.8
A3: China | B3: CHN | C3: Eastern Asia | D3: 0 | E3: 1 | F3: =IF(G3=1, 1, 0) -> 0 | G3: 0 | H3: 1 | I3: 0 | J3: 1 | K3: 0 | L3: 56.200512 | M3: {=INDEX('cumulative-co-emissions1850'!$D$1:$D$260000,MATCH(1, ('cumulative-co-emissions1850'!$C$1:$C$260000=2024)*('cumulative-co-emissions1850'!$B$1:$B$260000=Summary!$B3), 0)) - IFERROR(INDEX('cumulative-co-emissions1850'!$D$1:$D$260000,MATCH(1, ('cumulative-co-emissions1850'!$C$1:$C$260000=1850)*('cumulative-co-emissions1850'!$B$1:$B$260000=Summary!$B3), 0)), 0)} -> 285087040000 | N3: {=INDEX('cumulative-co-emissions1850'!$D$1:$D$260000,MATCH(1, ('cumulative-co-emissions1850'!$C$1:$C$260000=2024)*('cumulative-co-emissions1850'!$B$1:$B$260000=Summary!$B3), 0)) - IFERROR(INDEX('cumulative-co-emissions1850'!$D$1:$D$260000,MATCH(1, ('cumulative-co-emissions1850'!$C$1:$C$260000=1990)*('cumulative-co-emissions1850'!$B$1:$B$260000=Summary!$B3), 0)), 0)} -> 241692020000 | O3: 3.6185982e+08 | P3: 13590407 | Q3: 1410000000 | R3: 320.76273 | S3: 9.6385865 | T3: 15000000000000 | U3: 14700000000000 | V3: 24400000000000 | W3: 10640 | X3: 17321.667 | Y3: =VLOOKUP(B3,gain!$A$2:$AE$193, 31) -> 58.10219 | Z3: =IFERROR(VLOOKUP(B3,EIB!$B$2:$F$177, 2, FALSE), 0.1) -> 0.6 | AA3: =IFERROR(VLOOKUP(B3,EIB!$B$2:$F$177, 4, FALSE), 0.1) -> 0.4 | AB3: =VLOOKUP(B3,'UN Multilaterism Index'!$B$2:$C$194, 2,FALSE) -> 66.8
A4: Russian Federation | B4: RUS | C4: Eastern Europe | D4: 0 | E4: 1 | F4: 1 | G4: 0 | H4: 1 | I4: 1 | J4: 1 | K4: 0 | L4: 60.823019 | M4: {=INDEX('cumulative-co-emissions1850'!$D$1:$D$260000,MATCH(1, ('cumulative-co-emissions1850'!$C$1:$C$260000=2024)*('cumulative-co-emissions1850'!$B$1:$B$260000=Summary!$B4), 0)) - IFERROR(INDEX('cumulative-co-emissions1850'!$D$1:$D$260000,MATCH(1, ('cumulative-co-emissions1850'!$C$1:$C$260000=1850)*('cumulative-co-emissions1850'!$B$1:$B$260000=Summary!$B4), 0)), 0)} -> 122808115716 | N4: {=INDEX('cumulative-co-emissions1850'!$D$1:$D$260000,MATCH(1, ('cumulative-co-emissions1850'!$C$1:$C$260000=2024)*('cumulative-co-emissions1850'!$B$1:$B$260000=Summary!$B4), 0)) - IFERROR(INDEX('cumulative-co-emissions1850'!$D$1:$D$260000,MATCH(1, ('cumulative-co-emissions1850'!$C$1:$C$260000=1990)*('cumulative-co-emissions1850'!$B$1:$B$260000=Summary!$B4), 0)), 0)} -> 56260964000 | O4: 1.2219816e+08 | P4: 1488957.3 | Q4: 144000000 | R4: 1322.8284 | S4: 10.339981 | T4: 1610000000000 | U4: 1560000000000 | V4: 4350000000000 | W4: 11000 | X4: 29683.333 | Y4: =VLOOKUP(B4,gain!$A$2:$AE$193, 31) -> 52.499869 | Z4: =IFERROR(VLOOKUP(B4,EIB!$B$2:$F$177, 2, FALSE), 0.1) -> 0.1 | AA4: =IFERROR(VLOOKUP(B4,EIB!$B$2:$F$177, 4, FALSE), 0.1) -> 0 | AB4: =VLOOKUP(B4,'UN Multilaterism Index'!$B$2:$C$194, 2,FALSE) -> 48.5
A5: Germany | B5: DEU | C5: Western Europe | D5: 1 | E5: 1 | F5: =IF(G5=1, 1, 0) -> 1 | G5: 1 | H5: 1 | I5: 1 | J5: 1 | K5: 1 | L5: 70.291367 | M5: {=INDEX('cumulative-co-emissions1850'!$D$1:$D$260000,MATCH(1, ('cumulative-co-emissions1850'!$C$1:$C$260000=2024)*('cumulative-co-emissions1850'!$B$1:$B$260000=Summary!$B5), 0)) - IFERROR(INDEX('cumulative-co-emissions1850'!$D$1:$D$260000,MATCH(1, ('cumulative-co-emissions1850'!$C$1:$C$260000=1850)*('cumulative-co-emissions1850'!$B$1:$B$260000=Summary!$B5), 0)), 0)} -> 94881028340 | N5: {=INDEX('cumulative-co-emissions1850'!$D$1:$D$260000,MATCH(1, ('cumulative-co-emissions1850'!$C$1:$C$260000=2024)*('cumulative-co-emissions1850'!$B$1:$B$260000=Summary!$B5), 0)) - IFERROR(INDEX('cumulative-co-emissions1850'!$D$1:$D$260000,MATCH(1, ('cumulative-co-emissions1850'!$C$1:$C$260000=1990)*('cumulative-co-emissions1850'!$B$1:$B$260000=Summary!$B5), 0)), 0)} -> 28349913000 | O5: 74192966 | P5: 744556.31 | Q5: 83800000 | R5: 1388.3063 | S5: 8.8849202 | T5: 4080000000000 | U5: 4080000000000 | V5: 5060000000000 | W5: 49118.333 | X5: 60821.667 | Y5: =VLOOKUP(B5,gain!$A$2:$AE$193, 31) -> 62.893412 | Z5: =IFERROR(VLOOKUP(B5,EIB!$B$2:$F$177, 2, FALSE), 0.1) -> 0.1 | AA5: =IFERROR(VLOOKUP(B5,EIB!$B$2:$F$177, 4, FALSE), 0.1) -> 0.1 | AB5: =VLOOKUP(B5,'UN Multilaterism Index'!$B$2:$C$194, 2,FALSE) -> 73.3
A6: India | B6: IND | C6: Southern Asia | D6: 0 | E6: 0 | F6: =IF(G6=1, 1, 0) -> 0 | G6: 0 | H6: 1 | I6: 0 | J6: 0 | K6: 0 | L6: 43.207256 | M6: {=INDEX('cumulative-co-emissions1850'!$D$1:$D$260000,MATCH(1, ('cumulative-co-emissions1850'!$C$1:$C$260000=2024)*('cumulative-co-emissions1850'!$B$1:$B$260000=Summary!$B6), 0)) - IFERROR(INDEX('cumulative-co-emissions1850'!$D$1:$D$260000,MATCH(1, ('cumulative-co-emissions1850'!$C$1:$C$260000=1850)*('cumulative-co-emissions1850'!$B$1:$B$260000=Summary!$B6), 0)), 0)} -> 66072530000 | N6: {=INDEX('cumulative-co-emissions1850'!$D$1:$D$260000,MATCH(1, ('cumulative-co-emissions1850'!$C$1:$C$260000=2024)*('cumulative-co-emissions1850'!$B$1:$B$260000=Summary!$B6), 0)) - IFERROR(INDEX('cumulative-co-emissions1850'!$D$1:$D$260000,MATCH(1, ('cumulative-co-emissions1850'!$C$1:$C$260000=1990)*('cumulative-co-emissions1850'!$B$1:$B$260000=Summary!$B6), 0)), 0)} -> 55068026000 | O6: 1.1125597e+08 | P6: 3583238.2 | Q6: 1420000000 | R6: 108.3361 | S6: 2.5234072 | T6: 2850000000000 | U6: 2780000000000 | V6: 9560000000000 | W6: 2050 | X6: 6880 | Y6: =VLOOKUP(B6,gain!$A$2:$AE$193, 31) -> 54.597235 | Z6: =IFERROR(VLOOKUP(B6,EIB!$B$2:$F$177, 2, FALSE), 0.1) -> 1.2 | AA6: =IFERROR(VLOOKUP(B6,EIB!$B$2:$F$177, 4, FALSE), 0.1) -> 1 | AB6: =VLOOKUP(B6,'UN Multilaterism Index'!$B$2:$C$194, 2,FALSE) -> 63.5
A7: Brazil | B7: BRA | C7: Latin America and the Caribbean | D7: 0 | E7: 1 | F7: =IF(G7=1, 1, 0) -> 0 | G7: 0 | H7: 1 | I7: 0 | J7: 1 | K7: 0 | L7: 48.838478 | M7: {=INDEX('cumulative-co-emissions1850'!$D$1:$D$260000,MATCH(1, ('cumulative-co-emissions1850'!$C$1:$C$260000=2024)*('cumulative-co-emissions1850'!$B$1:$B$260000=Summary!$B7), 0)) - IFERROR(INDEX('cumulative-co-emissions1850'!$D$1:$D$260000,MATCH(1, ('cumulative-co-emissions1850'!$C$1:$C$260000=1850)*('cumulative-co-emissions1850'!$B$1:$B$260000=Summary!$B7), 0)), 0)} -> 18198706000 | N7: {=INDEX('cumulative-co-emissions1850'!$D$1:$D$260000,MATCH(1, ('cumulative-co-emissions1850'!$C$1:$C$260000=2024)*('cumulative-co-emissions1850'!$B$1:$B$260000=Summary!$B7), 0)) - IFERROR(INDEX('cumulative-co-emissions1850'!$D$1:$D$260000,MATCH(1, ('cumulative-co-emissions1850'!$C$1:$C$260000=1990)*('cumulative-co-emissions1850'!$B$1:$B$260000=Summary!$B7), 0)), 0)} -> 13487138600 | O7: 94928204 | P7: 1343312.8 | Q7: 215000000 | R7: 623.12289 | S7: 6.2479665 | T7: 1800000000000 | U7: 1730000000000 | V7: 3230000000000 | W7: 8488.3333 | X7: 15211.667 | Y7: =VLOOKUP(B7,gain!$A$2:$AE$193, 31) -> 47.155729 | Z7: =IFERROR(VLOOKUP(B7,EIB!$B$2:$F$177, 2, FALSE), 0.1) -> 0.4 | AA7: =IFERROR(VLOOKUP(B7,EIB!$B$2:$F$177, 4, FALSE), 0.1) -> 0.2 | AB7: =VLOOKUP(B7,'UN Multilaterism Index'!$B$2:$C$194, 2,FALSE) -> 77.2
A8: United Kingdom | B8: GBR | C8: Northern Europe | D8: 1 | E8: 1 | F8: =IF(G8=1, 1, 0) -> 1 | G8: 1 | H8: 1 | I8: 1 | J8: 1 | K8: 1 | L8: 70.353398 | M8: {=INDEX('cumulative-co-emissions1850'!$D$1:$D$260000,MATCH(1, ('cumulative-co-emissions1850'!$C$1:$C$260000=2024)*('cumulative-co-emissions1850'!$B$1:$B$260000=Summary!$B8), 0)) - IFERROR(INDEX('cumulative-co-emissions1850'!$D$1:$D$260000,MATCH(1, ('cumulative-co-emissions1850'!$C$1:$C$260000=1850)*('cumulative-co-emissions1850'!$B$1:$B$260000=Summary!$B8), 0)), 0)} -> 76367024500 | N8: {=INDEX('cumulative-co-emissions1850'!$D$1:$D$260000,MATCH(1, ('cumulative-co-emissions1850'!$C$1:$C$260000=2024)*('cumulative-co-emissions1850'!$B$1:$B$260000=Summary!$B8), 0)) - IFERROR(INDEX('cumulative-co-emissions1850'!$D$1:$D$260000,MATCH(1, ('cumulative-co-emissions1850'!$C$1:$C$260000=1990)*('cumulative-co-emissions1850'!$B$1:$B$260000=Summary!$B8), 0)), 0)} -> 16731560000 | O8: 62122297 | P8: 427093.25 | Q8: 67000000 | R8: 1539.3159 | S8: 6.3745261 | T8: 2900000000000 | U8: 2900000000000 | V8: 3330000000000 | W8: 43410 | X8: 49953.333 | Y8: =VLOOKUP(B8,gain!$A$2:$AE$193, 31) -> 39.963468 | Z8: =IFERROR(VLOOKUP(B8,EIB!$B$2:$F$177, 2, FALSE), 0.1) -> 0.1 | AA8: =IFERROR(VLOOKUP(B8,EIB!$B$2:$F$177, 4, FALSE), 0.1) -> 0 | AB8: =VLOOKUP(B8,'UN Multilaterism Index'!$B$2:$C$194, 2,FALSE) -> 58.9
A9: Japan | B9: JPN | C9: Eastern Asia | D9: 1 | E9: 1 | F9: =IF(G9=1, 1, 0) -> 1 | G9: 1 | H9: 1 | I9: 1 | J9: 1 | K9: 1 | L9: 65.638973 | M9: {=INDEX('cumulative-co-emissions1850'!$D$1:$D$260000,MATCH(1, ('cumulative-co-emissions1850'!$C$1:$C$260000=2024)*('cumulative-co-emissions1850'!$B$1:$B$260000=Summary!$B9), 0)) - IFERROR(INDEX('cumulative-co-emissions1850'!$D$1:$D$260000,MATCH(1, ('cumulative-co-emissions1850'!$C$1:$C$260000=1850)*('cumulative-co-emissions1850'!$B$1:$B$260000=Summary!$B9), 0)), 0)} -> 69612280000 | N9: {=INDEX('cumulative-co-emissions1850'!$D$1:$D$260000,MATCH(1, ('cumulative-co-emissions1850'!$C$1:$C$260000=2024)*('cumulative-co-emissions1850'!$B$1:$B$260000=Summary!$B9), 0)) - IFERROR(INDEX('cumulative-co-emissions1850'!$D$1:$D$260000,MATCH(1, ('cumulative-co-emissions1850'!$C$1:$C$260000=1990)*('cumulative-co-emissions1850'!$B$1:$B$260000=Summary!$B9), 0)), 0)} -> 40747444000 | O9: 59248604 | P9: 1119412.7 | Q9: 125000000 | R9: 618.14918 | S9: 8.9553016 | T9: 5260000000000 | U9: 5260000000000 | V9: 5710000000000 | W9: 41643.333 | X9: 45210 | Y9: =VLOOKUP(B9,gain!$A$2:$AE$193, 31) -> 65.381115 | Z9: =IFERROR(VLOOKUP(B9,EIB!$B$2:$F$177, 2, FALSE), 0.1) -> 0.4 | AA9: =IFERROR(VLOOKUP(B9,EIB!$B$2:$F$177, 4, FALSE), 0.1) -> 0.1 | AB9: =VLOOKUP(B9,'UN Multilaterism Index'!$B$2:$C$194, 2,FALSE) -> 76.2
A10: Canada | B10: CAN | C10: Northern America | D10: 1 | E10: 1 | F10: =IF(G10=1, 1, 0) -> 1 | G10: 1 | H10: 1 | I10: 1 | J10: 1 | K10: 1 | L10: 68.391612 | M10: {=INDEX('cumulative-co-emissions1850'!$D$1:$D$260000,MATCH(1, ('cumulative-co-emissions1850'!$C$1:$C$260000=2024)*('cumulative-co-emissions1850'!$B$1:$B$260000=Summary!$B10), 0)) - IFERROR(INDEX('cumulative-co-emissions1850'!$D$1:$D$260000,MATCH(1, ('cumulative-co-emissions1850'!$C$1:$C$260000=1850)*('cumulative-co-emissions1850'!$B$1:$B$260000=Summary!$B10), 0)), 0)} -> 35643701312 | N10: {=INDEX('cumulative-co-emissions1850'!$D$1:$D$260000,MATCH(1, ('cumulative-co-emissions1850'!$C$1:$C$260000=2024)*('cumulative-co-emissions1850'!$B$1:$B$260000=Summary!$B10), 0)) - IFERROR(INDEX('cumulative-co-emissions1850'!$D$1:$D$260000,MATCH(1, ('cumulative-co-emissions1850'!$C$1:$C$260000=1990)*('cumulative-co-emissions1850'!$B$1:$B$260000=Summary!$B10), 0)), 0)} -> 18477755000 | O10: 40705235 | P10: 668847.52 | Q10: 38900000 | R10: 1530.1975 | S10: 17.194024 | T10: 1770000000000 | U10: 1770000000000 | V10: 1960000000000 | W10: 46766.667 | X10: 51805 | Y10: =VLOOKUP(B10,gain!$A$2:$AE$193, 31) -> 32.881356 | Z10: =IFERROR(VLOOKUP(B10,EIB!$B$2:$F$177, 2, FALSE), 0.1) -> 0.1 | AA10: =IFERROR(VLOOKUP(B10,EIB!$B$2:$F$177, 4, FALSE), 0.1) -> 0 | AB10: =VLOOKUP(B10,'UN Multilaterism Index'!$B$2:$C$194, 2,FALSE) -> 63.6
A11: France | B11: FRA | C11: Western Europe | D11: 1 | E11: 1 | F11: =IF(G11=1, 1, 0) -> 1 | G11: 1 | H11: 1 | I11: 1 | J11: 1 | K11: 1 | L11: 67.538442 | M11: {=INDEX('cumulative-co-emissions1850'!$D$1:$D$260000,MATCH(1, ('cumulative-co-emissions1850'!$C$1:$C$260000=2024)*('cumulative-co-emissions1850'!$B$1:$B$260000=Summary!$B11), 0)) - IFERROR(INDEX('cumulative-co-emissions1850'!$D$1:$D$260000,MATCH(1, ('cumulative-co-emissions1850'!$C$1:$C$260000=1850)*('cumulative-co-emissions1850'!$B$1:$B$260000=Summary!$B11), 0)), 0)} -> 39707144760 | N11: {=INDEX('cumulative-co-emissions1850'!$D$1:$D$260000,MATCH(1, ('cumulative-co-emissions1850'!$C$1:$C$260000=2024)*('cumulative-co-emissions1850'!$B$1:$B$260000=Summary!$B11), 0)) - IFERROR(INDEX('cumulative-co-emissions1850'!$D$1:$D$260000,MATCH(1, ('cumulative-co-emissions1850'!$C$1:$C$260000=1990)*('cumulative-co-emissions1850'!$B$1:$B$260000=Summary!$B11), 0)), 0)} -> 12487957000 | O11: 36307133 | P11: 389864.86 | Q11: 68000000 | R11: 837.11966 | S11: 5.7333068 | T11: 2810000000000 | U11: 2810000000000 | V11: 3480000000000 | W11: 41716.667 | X11: 51508.333 | Y11: =VLOOKUP(B11,gain!$A$2:$AE$193, 31) -> 67.199891 | Z11: =IFERROR(VLOOKUP(B11,EIB!$B$2:$F$177, 2, FALSE), 0.1) -> 0.1 | AA11: =IFERROR(VLOOKUP(B11,EIB!$B$2:$F$177, 4, FALSE), 0.1) -> 0.1 | AB11: =VLOOKUP(B11,'UN Multilaterism Index'!$B$2:$C$194, 2,FALSE) -> 55.5
A12: Australia | B12: AUS | C12: Australia and New Zealand | D12: 1 | E12: 1 | F12: =IF(G12=1, 1, 0) -> 1 | G12: 1 | H12: 1 | I12: 1 | J12: 1 | K12: 1 | L12: 69.21649 | M12: {=INDEX('cumulative-co-emissions1850'!$D$1:$D$260000,MATCH(1, ('cumulative-co-emissions1850'!$C$1:$C$260000=2024)*('cumulative-co-emissions1850'!$B$1:$B$260000=Summary!$B12), 0)) - IFERROR(INDEX('cumulative-co-emissions1850'!$D$1:$D$260000,MATCH(1, ('cumulative-co-emissions1850'!$C$1:$C$260000=1850)*('cumulative-co-emissions1850'!$B$1:$B$260000=Summary!$B12), 0)), 0)} -> 20038763893 | N12: {=INDEX('cumulative-co-emissions1850'!$D$1:$D$260000,MATCH(1, ('cumulative-co-emissions1850'!$C$1:$C$260000=2024)*('cumulative-co-emissions1850'!$B$1:$B$260000=Summary!$B12), 0)) - IFERROR(INDEX('cumulative-co-emissions1850'!$D$1:$D$260000,MATCH(1, ('cumulative-co-emissions1850'!$C$1:$C$260000=1990)*('cumulative-co-emissions1850'!$B$1:$B$260000=Summary!$B12), 0)), 0)} -> 12570500300 | O12: 33322794 | P12: 473941.02 | Q12: 26000000 | R12: 1867.604 | S12: 18.228501 | T12: 1400000000000 | U12: 1400000000000 | V12: 1350000000000 | W12: 55226.667 | X12: 53211.667 | Y12: =VLOOKUP(B12,gain!$A$2:$AE$193, 31) -> 69.197042 | Z12: =IFERROR(VLOOKUP(B12,EIB!$B$2:$F$177, 2, FALSE), 0.1) -> 0.5 | AA12: =IFERROR(VLOOKUP(B12,EIB!$B$2:$F$177, 4, FALSE), 0.1) -> 0.2 | AB12: =VLOOKUP(B12,'UN Multilaterism Index'!$B$2:$C$194, 2,FALSE) -> 59.6
A13: Indonesia | B13: IDN | C13: South-eastern Asia | D13: 0 | E13: 1 | F13: =IF(G13=1, 1, 0) -> 0 | G13: 0 | H13: 1 | I13: 0 | J13: 0 | K13: 0 | L13: 47.084337 | M13: {=INDEX('cumulative-co-emissions1850'!$D$1:$D$260000,MATCH(1, ('cumulative-co-emissions1850'!$C$1:$C$260000=2024)*('cumulative-co-emissions1850'!$B$1:$B$260000=Summary!$B13), 0)) - IFERROR(INDEX('cumulative-co-emissions1850'!$D$1:$D$260000,MATCH(1, ('cumulative-co-emissions1850'!$C$1:$C$260000=1850)*('cumulative-co-emissions1850'!$B$1:$B$260000=Summary!$B13), 0)), 0)} -> 17419934000 | N13: {=INDEX('cumulative-co-emissions1850'!$D$1:$D$260000,MATCH(1, ('cumulative-co-emissions1850'!$C$1:$C$260000=2024)*('cumulative-co-emissions1850'!$B$1:$B$260000=Summary!$B13), 0)) - IFERROR(INDEX('cumulative-co-emissions1850'!$D$1:$D$260000,MATCH(1, ('cumulative-co-emissions1850'!$C$1:$C$260000=1990)*('cumulative-co-emissions1850'!$B$1:$B$260000=Summary!$B13), 0)), 0)} -> 14516532000 | O13: 56763813 | P13: 1949064.9 | Q13: 276000000 | R13: 266.41699 | S13: 7.0618293 | T13: 1090000000000 | U13: 1040000000000 | V13: 3280000000000 | W13: 4016.6667 | X13: 12118.333 | Y13: =VLOOKUP(B13,gain!$A$2:$AE$193, 31) -> 54.597235 | Z13: =IFERROR(VLOOKUP(B13,EIB!$B$2:$F$177, 2, FALSE), 0.1) -> 0.5 | AA13: =IFERROR(VLOOKUP(B13,EIB!$B$2:$F$177, 4, FALSE), 0.1) -> 0.4 | AB13: =VLOOKUP(B13,'UN Multilaterism Index'!$B$2:$C$194, 2,FALSE) -> 74.5
A14: Qatar | B14: QAT | C14: Western Asia | D14: 0 | E14: 1 | F14: =IF(G14=1, 1, 0) -> 0 | G14: 0 | H14: 1 | I14: 1 | J14: 1 | K14: 1 | L14: 57.54447 | M14: {=INDEX('cumulative-co-emissions1850'!$D$1:$D$260000,MATCH(1, ('cumulative-co-emissions1850'!$C$1:$C$260000=2024)*('cumulative-co-emissions1850'!$B$1:$B$260000=Summary!$B14), 0)) - IFERROR(INDEX('cumulative-co-emissions1850'!$D$1:$D$260000,MATCH(1, ('cumulative-co-emissions1850'!$C$1:$C$260000=1850)*('cumulative-co-emissions1850'!$B$1:$B$260000=Summary!$B14), 0)), 0)} -> 2590880000 | N14: {=INDEX('cumulative-co-emissions1850'!$D$1:$D$260000,MATCH(1, ('cumulative-co-emissions1850'!$C$1:$C$260000=2024)*('cumulative-co-emissions1850'!$B$1:$B$260000=Summary!$B14), 0)) - IFERROR(INDEX('cumulative-co-emissions1850'!$D$1:$D$260000,MATCH(1, ('cumulative-co-emissions1850'!$C$1:$C$260000=1990)*('cumulative-co-emissions1850'!$B$1:$B$260000=Summary!$B14), 0)), 0)} -> 2297528320 | O14: 3988936.6 | P14: 198791.04 | Q14: 2700000 | R14: 1574.476 | S14: 73.626311 | T14: 168000000000 | U14: 168000000000 | V14: 264000000000 | W14: 61508.333 | X14: 96490 | Y14: =VLOOKUP(B14,gain!$A$2:$AE$193, 31) -> 52.499869 | Z14: =IFERROR(VLOOKUP(B14,EIB!$B$2:$F$177, 2, FALSE), 0.1) -> 1.5 | AA14: =IFERROR(VLOOKUP(B14,EIB!$B$2:$F$177, 4, FALSE), 0.1) -> 1.2 | AB14: =VLOOKUP(B14,'UN Multilaterism Index'!$B$2:$C$194, 2,FALSE) -> 76
A15: Singapore | B15: SGP | C15: South-eastern Asia | D15: 0 | E15: 1 | F15: =IF(G15=1, 1, 0) -> 0 | G15: 0 | H15: 0 | I15: 1 | J15: 1 | K15: 1 | L15: 71.419441 | M15: {=INDEX('cumulative-co-emissions1850'!$D$1:$D$260000,MATCH(1, ('cumulative-co-emissions1850'!$C$1:$C$260000=2024)*('cumulative-co-emissions1850'!$B$1:$B$260000=Summary!$B15), 0)) - IFERROR(INDEX('cumulative-co-emissions1850'!$D$1:$D$260000,MATCH(1, ('cumulative-co-emissions1850'!$C$1:$C$260000=1850)*('cumulative-co-emissions1850'!$B$1:$B$260000=Summary!$B15), 0)), 0)} -> 2247705300 | N15: {=INDEX('cumulative-co-emissions1850'!$D$1:$D$260000,MATCH(1, ('cumulative-co-emissions1850'!$C$1:$C$260000=2024)*('cumulative-co-emissions1850'!$B$1:$B$260000=Summary!$B15), 0)) - IFERROR(INDEX('cumulative-co-emissions1850'!$D$1:$D$260000,MATCH(1, ('cumulative-co-emissions1850'!$C$1:$C$260000=1990)*('cumulative-co-emissions1850'!$B$1:$B$260000=Summary!$B15), 0)), 0)} -> 1572990200 | O15: 1514620.3 | P15: 57495.371 | Q15: 5640000 | R15: 298.31151 | S15: 10.194215 | T15: 333000000000 | U15: 333000000000 | V15: 525000000000 | W15: 59308.333 | X15: 93505 | Y15: =VLOOKUP(B15,gain!$A$2:$AE$193, 31) -> 40.379899 | Z15: =IFERROR(VLOOKUP(B15,EIB!$B$2:$F$177, 2, FALSE), 0.1) -> 0.3 | AA15: =IFERROR(VLOOKUP(B15,EIB!$B$2:$F$177, 4, FALSE), 0.1) -> 0 | AB15: =VLOOKUP(B15,'UN Multilaterism Index'!$B$2:$C$194, 2,FALSE) -> 68.5
A16: Italy | B16: ITA | C16: Southern Europe | D16: 1 | E16: 1 | F16: =IF(G16=1, 1, 0) -> 1 | G16: 1 | H16: 1 | I16: 1 | J16: 1 | K16: 1 | L16: 59.625025 | M16: {=INDEX('cumulative-co-emissions1850'!$D$1:$D$260000,MATCH(1, ('cumulative-co-emissions1850'!$C$1:$C$260000=2024)*('cumulative-co-emissions1850'!$B$1:$B$260000=Summary!$B16), 0)) - IFERROR(INDEX('cumulative-co-emissions1850'!$D$1:$D$260000,MATCH(1, ('cumulative-co-emissions1850'!$C$1:$C$260000=1850)*('cumulative-co-emissions1850'!$B$1:$B$260000=Summary!$B16), 0)), 0)} -> 26005944000 | N16: {=INDEX('cumulative-co-emissions1850'!$D$1:$D$260000,MATCH(1, ('cumulative-co-emissions1850'!$C$1:$C$260000=2024)*('cumulative-co-emissions1850'!$B$1:$B$260000=Summary!$B16), 0)) - IFERROR(INDEX('cumulative-co-emissions1850'!$D$1:$D$260000,MATCH(1, ('cumulative-co-emissions1850'!$C$1:$C$260000=1990)*('cumulative-co-emissions1850'!$B$1:$B$260000=Summary!$B16), 0)), 0)} -> 14133844000 | O16: 25171864 | P16: 381739.49 | Q16: 58900000 | R16: 586.47699 | S16: 6.4811458 | T16: 2060000000000 | U16: 2060000000000 | V16: 2820000000000 | W16: 34533.333 | X16: 47236.667 | Y16: =VLOOKUP(B16,gain!$A$2:$AE$193, 31) -> 58.801516 | Z16: =IFERROR(VLOOKUP(B16,EIB!$B$2:$F$177, 2, FALSE), 0.1) -> 0.1 | AA16: =IFERROR(VLOOKUP(B16,EIB!$B$2:$F$177, 4, FALSE), 0.1) -> 0.1 | AB16: =VLOOKUP(B16,'UN Multilaterism Index'!$B$2:$C$194, 2,FALSE) -> 68.4
... A18: Norway | B18: NOR | C18: Northern Europe | D18: 1 | E18: 1 | F18: =IF(G18=1, 1, 0) -> 1 | G18: 1 | H18: 1 | I18: 1 | J18: 1 | K18: 1 | L18: 75.670164 | M18: {=INDEX('cumulative-co-emissions1850'!$D$1:$D$260000,MATCH(1, ('cumulative-co-emissions1850'!$C$1:$C$260000=2024)*('cumulative-co-emissions1850'!$B$1:$B$260000=Summary!$B18), 0)) - IFERROR(INDEX('cumulative-co-emissions1850'!$D$1:$D$260000,MATCH(1, ('cumulative-co-emissions1850'!$C$1:$C$260000=1850)*('cumulative-co-emissions1850'!$B$1:$B$260000=Summary!$B18), 0)), 0)} -> 2786141040 | N18: {=INDEX('cumulative-co-emissions1850'!$D$1:$D$260000,MATCH(1, ('cumulative-co-emissions1850'!$C$1:$C$260000=2024)*('cumulative-co-emissions1850'!$B$1:$B$260000=Summary!$B18), 0)) - IFERROR(INDEX('cumulative-co-emissions1850'!$D$1:$D$260000,MATCH(1, ('cumulative-co-emissions1850'!$C$1:$C$260000=1990)*('cumulative-co-emissions1850'!$B$1:$B$260000=Summary!$B18), 0)), 0)} -> 1429899000 | O18: 3038177.6 | P18: 31821.315 | Q18: 5460000 | R18: 900.80117 | S18: 5.8280797 | T18: 442000000000 | U18: 442000000000 | V18: 445000000000 | W18: 82408.333 | X18: 82821.667 | Y18: =VLOOKUP(B18,gain!$A$2:$AE$193, 31) -> 52.499869 | Z18: =IFERROR(VLOOKUP(B18,EIB!$B$2:$F$177, 2, FALSE), 0.1) -> 0.1 | AA18: =IFERROR(VLOOKUP(B18,EIB!$B$2:$F$177, 4, FALSE), 0.1) -> 0 | AB18: =VLOOKUP(B18,'UN Multilaterism Index'!$B$2:$C$194, 2,FALSE) -> 68.5
A19: Poland | B19: POL | C19: Eastern Europe | D19: 1 | E19: 1 | F19: 1 | G19: 0 | H19: 1 | I19: 1 | J19: 1 | K19: 1 | L19: 61.767873 | M19: {=INDEX('cumulative-co-emissions1850'!$D$1:$D$260000,MATCH(1, ('cumulative-co-emissions1850'!$C$1:$C$260000=2024)*('cumulative-co-emissions1850'!$B$1:$B$260000=Summary!$B19), 0)) - IFERROR(INDEX('cumulative-co-emissions1850'!$D$1:$D$260000,MATCH(1, ('cumulative-co-emissions1850'!$C$1:$C$260000=1850)*('cumulative-co-emissions1850'!$B$1:$B$260000=Summary!$B19), 0)), 0)} -> 28980557450 | N19: {=INDEX('cumulative-co-emissions1850'!$D$1:$D$260000,MATCH(1, ('cumulative-co-emissions1850'!$C$1:$C$260000=2024)*('cumulative-co-emissions1850'!$B$1:$B$260000=Summary!$B19), 0)) - IFERROR(INDEX('cumulative-co-emissions1850'!$D$1:$D$260000,MATCH(1, ('cumulative-co-emissions1850'!$C$1:$C$260000=1990)*('cumulative-co-emissions1850'!$B$1:$B$260000=Summary!$B19), 0)), 0)} -> 11210070000 | O19: 26596275 | P19: 360640.22 | Q19: 36800000 | R19: 1106.1846 | S19: 9.800006 | T19: 586000000000 | U19: 586000000000 | V19: 1330000000000 | W19: 15551.667 | X19: 35286.667 | Y19: =VLOOKUP(B19,gain!$A$2:$AE$193, 31) -> 52.499869 | Z19: =IFERROR(VLOOKUP(B19,EIB!$B$2:$F$177, 2, FALSE), 0.1) -> 0.1 | AA19: =IFERROR(VLOOKUP(B19,EIB!$B$2:$F$177, 4, FALSE), 0.1) -> 0.1 | AB19: =VLOOKUP(B19,'UN Multilaterism Index'!$B$2:$C$194, 2,FALSE) -> 63.6
A20: Ukraine | B20: UKR | C20: Eastern Europe | D20: 0 | E20: 0 | F20: 1 | G20: 0 | H20: 1 | I20: 0 | J20: 1 | K20: 0 | L20: 52.893982 | M20: {=INDEX('cumulative-co-emissions1850'!$D$1:$D$260000,MATCH(1, ('cumulative-co-emissions1850'!$C$1:$C$260000=2024)*('cumulative-co-emissions1850'!$B$1:$B$260000=Summary!$B20), 0)) - IFERROR(INDEX('cumulative-co-emissions1850'!$D$1:$D$260000,MATCH(1, ('cumulative-co-emissions1850'!$C$1:$C$260000=1850)*('cumulative-co-emissions1850'!$B$1:$B$260000=Summary!$B20), 0)), 0)} -> 31236458751 | N20: {=INDEX('cumulative-co-emissions1850'!$D$1:$D$260000,MATCH(1, ('cumulative-co-emissions1850'!$C$1:$C$260000=2024)*('cumulative-co-emissions1850'!$B$1:$B$260000=Summary!$B20), 0)) - IFERROR(INDEX('cumulative-co-emissions1850'!$D$1:$D$260000,MATCH(1, ('cumulative-co-emissions1850'!$C$1:$C$260000=1990)*('cumulative-co-emissions1850'!$B$1:$B$260000=Summary!$B20), 0)), 0)} -> 10393563000 | O20: 35893566 | P20: 261938.21 | Q20: 38000000 | R20: 1491.1236 | S20: 6.8931108 | T20: 138000000000 | U20: 121000000000 | V20: 537000000000 | W20: 3393.3333 | X20: 13151.667 | Y20: =VLOOKUP(B20,gain!$A$2:$AE$193, 31) -> 69.853875 | Z20: =IFERROR(VLOOKUP(B20,EIB!$B$2:$F$177, 2, FALSE), 0.1) -> 0.2 | AA20: =IFERROR(VLOOKUP(B20,EIB!$B$2:$F$177, 4, FALSE), 0.1) -> 0 | AB20: =VLOOKUP(B20,'UN Multilaterism Index'!$B$2:$C$194, 2,FALSE) -> 50.3
A21: United Arab Emirates | B21: ARE | C21: Western Asia | D21: 0 | E21: 1 | F21: =IF(G21=1, 1, 0) -> 0 | G21: 0 | H21: 1 | I21: 1 | J21: 1 | K21: 1 | L21: 60.479317 | M21: {=INDEX('cumulative-co-emissions1850'!$D$1:$D$260000,MATCH(1, ('cumulative-co-emissions1850'!$C$1:$C$260000=2024)*('cumulative-co-emissions1850'!$B$1:$B$260000=Summary!$B21), 0)) - IFERROR(INDEX('cumulative-co-emissions1850'!$D$1:$D$260000,MATCH(1, ('cumulative-co-emissions1850'!$C$1:$C$260000=1850)*('cumulative-co-emissions1850'!$B$1:$B$260000=Summary!$B21), 0)), 0)} -> 5824239600 | N21: {=INDEX('cumulative-co-emissions1850'!$D$1:$D$260000,MATCH(1, ('cumulative-co-emissions1850'!$C$1:$C$260000=2024)*('cumulative-co-emissions1850'!$B$1:$B$260000=Summary!$B21), 0)) - IFERROR(INDEX('cumulative-co-emissions1850'!$D$1:$D$260000,MATCH(1, ('cumulative-co-emissions1850'!$C$1:$C$260000=1990)*('cumulative-co-emissions1850'!$B$1:$B$260000=Summary!$B21), 0)), 0)} -> 4997699630 | O21: 6147745.3 | P21: 299588.73 | Q21: 9440000 | R21: 698.55193 | S21: 31.736094 | T21: 412000000000 | U21: 412000000000 | V21: 705000000000 | W21: 44500 | X21: 76111.667 | Y21: =VLOOKUP(B21,gain!$A$2:$AE$193, 31) -> 49.747451 | Z21: =IFERROR(VLOOKUP(B21,EIB!$B$2:$F$177, 2, FALSE), 0.1) -> 1.1 | AA21: =IFERROR(VLOOKUP(B21,EIB!$B$2:$F$177, 4, FALSE), 0.1) -> 0.9 | AB21: =VLOOKUP(B21,'UN Multilaterism Index'!$B$2:$C$194, 2,FALSE) -> 66.7
A22: Netherlands | B22: NLD | C22: Western Europe | D22: 1 | E22: 1 | F22: =IF(G22=1, 1, 0) -> 1 | G22: 1 | H22: 1 | I22: 1 | J22: 1 | K22: 1 | L22: 66.822981 | M22: {=INDEX('cumulative-co-emissions1850'!$D$1:$D$260000,MATCH(1, ('cumulative-co-emissions1850'!$C$1:$C$260000=2024)*('cumulative-co-emissions1850'!$B$1:$B$260000=Summary!$B22), 0)) - IFERROR(INDEX('cumulative-co-emissions1850'!$D$1:$D$260000,MATCH(1, ('cumulative-co-emissions1850'!$C$1:$C$260000=1850)*('cumulative-co-emissions1850'!$B$1:$B$260000=Summary!$B22), 0)), 0)} -> 12244849600 | N22: {=INDEX('cumulative-co-emissions1850'!$D$1:$D$260000,MATCH(1, ('cumulative-co-emissions1850'!$C$1:$C$260000=2024)*('cumulative-co-emissions1850'!$B$1:$B$260000=Summary!$B22), 0)) - IFERROR(INDEX('cumulative-co-emissions1850'!$D$1:$D$260000,MATCH(1, ('cumulative-co-emissions1850'!$C$1:$C$260000=1990)*('cumulative-co-emissions1850'!$B$1:$B$260000=Summary!$B22), 0)), 0)} -> 5602440500 | O22: 12225707 | P22: 163554.41 | Q22: 17700000 | R22: 984.10129 | S22: 9.2403621 | T22: 921000000000 | U22: 921000000000 | V22: 1080000000000 | W22: 52885 | X22: 62270 | Y22: =VLOOKUP(B22,gain!$A$2:$AE$193, 31) -> 52.499869 | Z22: =IFERROR(VLOOKUP(B22,EIB!$B$2:$F$177, 2, FALSE), 0.1) -> 0.1 | AA22: =IFERROR(VLOOKUP(B22,EIB!$B$2:$F$177, 4, FALSE), 0.1) -> 0.1 | AB22: =VLOOKUP(B22,'UN Multilaterism Index'!$B$2:$C$194, 2,FALSE) -> 70.3
A23: Ireland | B23: IRL | C23: Northern Europe | D23: 1 | E23: 1 | F23: =IF(G23=1, 1, 0) -> 1 | G23: 1 | H23: 1 | I23: 1 | J23: 1 | K23: 1 | L23: 65.258415 | M23: {=INDEX('cumulative-co-emissions1850'!$D$1:$D$260000,MATCH(1, ('cumulative-co-emissions1850'!$C$1:$C$260000=2024)*('cumulative-co-emissions1850'!$B$1:$B$260000=Summary!$B23), 0)) - IFERROR(INDEX('cumulative-co-emissions1850'!$D$1:$D$260000,MATCH(1, ('cumulative-co-emissions1850'!$C$1:$C$260000=1850)*('cumulative-co-emissions1850'!$B$1:$B$260000=Summary!$B23), 0)), 0)} -> 2366029888 | N23: {=INDEX('cumulative-co-emissions1850'!$D$1:$D$260000,MATCH(1, ('cumulative-co-emissions1850'!$C$1:$C$260000=2024)*('cumulative-co-emissions1850'!$B$1:$B$260000=Summary!$B23), 0)) - IFERROR(INDEX('cumulative-co-emissions1850'!$D$1:$D$260000,MATCH(1, ('cumulative-co-emissions1850'!$C$1:$C$260000=1990)*('cumulative-co-emissions1850'!$B$1:$B$260000=Summary!$B23), 0)), 0)} -> 1357265340 | O23: 4206939.6 | P23: 68602.766 | Q23: 5130000 | R23: 1194.9502 | S23: 13.372859 | T23: 330000000000 | U23: 330000000000 | V23: 375000000000 | W23: 66455 | X23: 75358.333 | Y23: =VLOOKUP(B23,gain!$A$2:$AE$193, 31) -> 54.597235 | Z23: =IFERROR(VLOOKUP(B23,EIB!$B$2:$F$177, 2, FALSE), 0.1) -> 0.1 | AA23: =IFERROR(VLOOKUP(B23,EIB!$B$2:$F$177, 4, FALSE), 0.1) -> 0.1 | AB23: =VLOOKUP(B23,'UN Multilaterism Index'!$B$2:$C$194, 2,FALSE) -> 74.2
A24: Switzerland | B24: CHE | C24: Western Europe | D24: 1 | E24: 1 | F24: =IF(G24=1, 1, 0) -> 1 | G24: 1 | H24: 1 | I24: 1 | J24: 1 | K24: 1 | L24: 72.633593 | M24: {=INDEX('cumulative-co-emissions1850'!$D$1:$D$260000,MATCH(1, ('cumulative-co-emissions1850'!$C$1:$C$260000=2024)*('cumulative-co-emissions1850'!$B$1:$B$260000=Summary!$B24), 0)) - IFERROR(INDEX('cumulative-co-emissions1850'!$D$1:$D$260000,MATCH(1, ('cumulative-co-emissions1850'!$C$1:$C$260000=1850)*('cumulative-co-emissions1850'!$B$1:$B$260000=Summary!$B24), 0)), 0)} -> 3158062000 | N24: {=INDEX('cumulative-co-emissions1850'!$D$1:$D$260000,MATCH(1, ('cumulative-co-emissions1850'!$C$1:$C$260000=2024)*('cumulative-co-emissions1850'!$B$1:$B$260000=Summary!$B24), 0)) - IFERROR(INDEX('cumulative-co-emissions1850'!$D$1:$D$260000,MATCH(1, ('cumulative-co-emissions1850'!$C$1:$C$260000=1990)*('cumulative-co-emissions1850'!$B$1:$B$260000=Summary!$B24), 0)), 0)} -> 1410747600 | O24: 3139480.8 | P24: 42945.826 | Q24: 8780000 | R24: 526.90824 | S24: 4.8913241 | T24: 739000000000 | U24: 739000000000 | V24: 641000000000 | W24: 85740 | X24: 74380 | Y24: =VLOOKUP(B24,gain!$A$2:$AE$193, 31) -> 32.881356 | Z24: =IFERROR(VLOOKUP(B24,EIB!$B$2:$F$177, 2, FALSE), 0.1) -> 0.1 | AA24: =IFERROR(VLOOKUP(B24,EIB!$B$2:$F$177, 4, FALSE), 0.1) -> 0 | AB24: =VLOOKUP(B24,'UN Multilaterism Index'!$B$2:$C$194, 2,FALSE) -> 75.6
A25: Belgium | B25: BEL | C25: Western Europe | D25: 1 | E25: 1 | F25: =IF(G25=1, 1, 0) -> 1 | G25: 1 | H25: 1 | I25: 1 | J25: 1 | K25: 1 | L25: 63.468071 | M25: {=INDEX('cumulative-co-emissions1850'!$D$1:$D$260000,MATCH(1, ('cumulative-co-emissions1850'!$C$1:$C$260000=2024)*('cumulative-co-emissions1850'!$B$1:$B$260000=Summary!$B25), 0)) - IFERROR(INDEX('cumulative-co-emissions1850'!$D$1:$D$260000,MATCH(1, ('cumulative-co-emissions1850'!$C$1:$C$260000=1850)*('cumulative-co-emissions1850'!$B$1:$B$260000=Summary!$B25), 0)), 0)} -> 12755689860 | N25: {=INDEX('cumulative-co-emissions1850'!$D$1:$D$260000,MATCH(1, ('cumulative-co-emissions1850'!$C$1:$C$260000=2024)*('cumulative-co-emissions1850'!$B$1:$B$260000=Summary!$B25), 0)) - IFERROR(INDEX('cumulative-co-emissions1850'!$D$1:$D$260000,MATCH(1, ('cumulative-co-emissions1850'!$C$1:$C$260000=1990)*('cumulative-co-emissions1850'!$B$1:$B$260000=Summary!$B25), 0)), 0)} -> 3829417000 | O25: 10428192 | P25: 106384.4 | Q25: 11700000 | R25: 1405.443 | S25: 9.0926838 | T25: 553000000000 | U25: 553000000000 | V25: 671000000000 | W25: 47955 | X25: 58246.667 | Y25: =VLOOKUP(B25,gain!$A$2:$AE$193, 31) -> 48.330482 | Z25: =IFERROR(VLOOKUP(B25,EIB!$B$2:$F$177, 2, FALSE), 0.1) -> 0.1 | AA25: =IFERROR(VLOOKUP(B25,EIB!$B$2:$F$177, 4, FALSE), 0.1) -> 0.1 | AB25: =VLOOKUP(B25,'UN Multilaterism Index'!$B$2:$C$194, 2,FALSE) -> 65.4
A26: Saudi Arabia | B26: SAU | C26: Western Asia | D26: 0 | E26: 1 | F26: =IF(G26=1, 1, 0) -> 0 | G26: 0 | H26: 1 | I26: 1 | J26: 1 | K26: 1 | L26: 55.571583 | M26: {=INDEX('cumulative-co-emissions1850'!$D$1:$D$260000,MATCH(1, ('cumulative-co-emissions1850'!$C$1:$C$260000=2024)*('cumulative-co-emissions1850'!$B$1:$B$260000=Summary!$B26), 0)) - IFERROR(INDEX('cumulative-co-emissions1850'!$D$1:$D$260000,MATCH(1, ('cumulative-co-emissions1850'!$C$1:$C$260000=1850)*('cumulative-co-emissions1850'!$B$1:$B$260000=Summary!$B26), 0)), 0)} -> 19020340000 | N26: {=INDEX('cumulative-co-emissions1850'!$D$1:$D$260000,MATCH(1, ('cumulative-co-emissions1850'!$C$1:$C$260000=2024)*('cumulative-co-emissions1850'!$B$1:$B$260000=Summary!$B26), 0)) - IFERROR(INDEX('cumulative-co-emissions1850'!$D$1:$D$260000,MATCH(1, ('cumulative-co-emissions1850'!$C$1:$C$260000=1990)*('cumulative-co-emissions1850'!$B$1:$B$260000=Summary!$B26), 0)), 0)} -> 15857340400 | O26: 17694369 | P26: 704486.74 | Q26: 36400000 | R26: 563.87326 | S26: 19.354031 | T26: 827000000000 | U26: 827000000000 | V26: 1830000000000 | W26: 23215 | X26: 51266.667 | Y26: =VLOOKUP(B26,gain!$A$2:$AE$193, 31) -> 57.871405 | Z26: =IFERROR(VLOOKUP(B26,EIB!$B$2:$F$177, 2, FALSE), 0.1) -> 1.1 | AA26: =IFERROR(VLOOKUP(B26,EIB!$B$2:$F$177, 4, FALSE), 0.1) -> 0.8 | AB26: =VLOOKUP(B26,'UN Multilaterism Index'!$B$2:$C$194, 2,FALSE) -> 60.2
A27: Korea, Rep. | B27: KOR | C27: Eastern Asia | D27: 1 | E27: 1 | F27: =IF(G27=1, 1, 0) -> 0 | G27: 0 | H27: 1 | I27: 1 | J27: 1 | K27: 1 | L27: 67.725843 | M27: {=INDEX('cumulative-co-emissions1850'!$D$1:$D$260000,MATCH(1, ('cumulative-co-emissions1850'!$C$1:$C$260000=2024)*('cumulative-co-emissions1850'!$B$1:$B$260000=Summary!$B27), 0)) - IFERROR(INDEX('cumulative-co-emissions1850'!$D$1:$D$260000,MATCH(1, ('cumulative-co-emissions1850'!$C$1:$C$260000=1850)*('cumulative-co-emissions1850'!$B$1:$B$260000=Summary!$B27), 0)), 0)} -> 20707550000 | N27: {=INDEX('cumulative-co-emissions1850'!$D$1:$D$260000,MATCH(1, ('cumulative-co-emissions1850'!$C$1:$C$260000=2024)*('cumulative-co-emissions1850'!$B$1:$B$260000=Summary!$B27), 0)) - IFERROR(INDEX('cumulative-co-emissions1850'!$D$1:$D$260000,MATCH(1, ('cumulative-co-emissions1850'!$C$1:$C$260000=1990)*('cumulative-co-emissions1850'!$B$1:$B$260000=Summary!$B27), 0)), 0)} -> 17588288600 | O27: 20364223 | P27: 631189.83 | Q27: 51600000 | R27: 455.13893 | S27: 12.232361 | T27: 1730000000000 | U27: 1730000000000 | V27: 2370000000000 | W27: 33548.333 | X27: 45948.333 | Y27: =VLOOKUP(B27,gain!$A$2:$AE$193, 31) -> 67.405846 | Z27: =IFERROR(VLOOKUP(B27,EIB!$B$2:$F$177, 2, FALSE), 0.1) -> 0.3 | AA27: =IFERROR(VLOOKUP(B27,EIB!$B$2:$F$177, 4, FALSE), 0.1) -> 0 | AB27: =VLOOKUP(B27,'UN Multilaterism Index'!$B$2:$C$194, 2,FALSE) -> 63.3
A28: Denmark | B28: DNK | C28: Northern Europe | D28: 1 | E28: 1 | F28: =IF(G28=1, 1, 0) -> 1 | G28: 1 | H28: 1 | I28: 1 | J28: 1 | K28: 1 | L28: 71.803891 | M28: {=INDEX('cumulative-co-emissions1850'!$D$1:$D$260000,MATCH(1, ('cumulative-co-emissions1850'!$C$1:$C$260000=2024)*('cumulative-co-emissions1850'!$B$1:$B$260000=Summary!$B28), 0)) - IFERROR(INDEX('cumulative-co-emissions1850'!$D$1:$D$260000,MATCH(1, ('cumulative-co-emissions1850'!$C$1:$C$260000=1850)*('cumulative-co-emissions1850'!$B$1:$B$260000=Summary!$B28), 0)), 0)} -> 4197836628 | N28: {=INDEX('cumulative-co-emissions1850'!$D$1:$D$260000,MATCH(1, ('cumulative-co-emissions1850'!$C$1:$C$260000=2024)*('cumulative-co-emissions1850'!$B$1:$B$260000=Summary!$B28), 0)) - IFERROR(INDEX('cumulative-co-emissions1850'!$D$1:$D$260000,MATCH(1, ('cumulative-co-emissions1850'!$C$1:$C$260000=1990)*('cumulative-co-emissions1850'!$B$1:$B$260000=Summary!$B28), 0)), 0)} -> 1645986500 | O28: 4547147 | P28: 47932.926 | Q28: 5900000 | R28: 1144.9422 | S28: 8.1242247 | T28: 376000000000 | U28: 376000000000 | V28: 385000000000 | W28: 64488.333 | X28: 65995 | Y28: =VLOOKUP(B28,gain!$A$2:$AE$193, 31) -> 51.72724 | Z28: =IFERROR(VLOOKUP(B28,EIB!$B$2:$F$177, 2, FALSE), 0.1) -> 0.1 | AA28: =IFERROR(VLOOKUP(B28,EIB!$B$2:$F$177, 4, FALSE), 0.1) -> 0.1 | AB28: =VLOOKUP(B28,'UN Multilaterism Index'!$B$2:$C$194, 2,FALSE) -> 67.7
A29: Mexico | B29: MEX | C29: Latin America and the Caribbean | D29: 1 | E29: 1 | F29: =IF(G29=1, 1, 0) -> 0 | G29: 0 | H29: 1 | I29: 0 | J29: 1 | K29: 0 | L29: 49.0791 | M29: {=INDEX('cumulative-co-emissions1850'!$D$1:$D$260000,MATCH(1, ('cumulative-co-emissions1850'!$C$1:$C$260000=2024)*('cumulative-co-emissions1850'!$B$1:$B$260000=Summary!$B29), 0)) - IFERROR(INDEX('cumulative-co-emissions1850'!$D$1:$D$260000,MATCH(1, ('cumulative-co-emissions1850'!$C$1:$C$260000=1850)*('cumulative-co-emissions1850'!$B$1:$B$260000=Summary!$B29), 0)), 0)} -> 22015853000 | N29: {=INDEX('cumulative-co-emissions1850'!$D$1:$D$260000,MATCH(1, ('cumulative-co-emissions1850'!$C$1:$C$260000=2024)*('cumulative-co-emissions1850'!$B$1:$B$260000=Summary!$B29), 0)) - IFERROR(INDEX('cumulative-co-emissions1850'!$D$1:$D$260000,MATCH(1, ('cumulative-co-emissions1850'!$C$1:$C$260000=1990)*('cumulative-co-emissions1850'!$B$1:$B$260000=Summary!$B29), 0)), 0)} -> 14610996000 | O29: 28288889 | P29: 638920.44 | Q29: 128000000 | R29: 322.20975 | S29: 4.9915659 | T29: 1220000000000 | U29: 1150000000000 | V29: 2590000000000 | W29: 9758.3333 | X29: 20635 | Y29: =VLOOKUP(B29,gain!$A$2:$AE$193, 31) -> 52.499869 | Z29: =IFERROR(VLOOKUP(B29,EIB!$B$2:$F$177, 2, FALSE), 0.1) -> 0.4 | AA29: =IFERROR(VLOOKUP(B29,EIB!$B$2:$F$177, 4, FALSE), 0.1) -> 0.2 | AB29: =VLOOKUP(B29,'UN Multilaterism Index'!$B$2:$C$194, 2,FALSE) -> 76.5
A30: Austria | B30: AUT | C30: Western Europe | D30: 1 | E30: 1 | F30: =IF(G30=1, 1, 0) -> 1 | G30: 1 | H30: 1 | I30: 1 | J30: 1 | K30: 1 | L30: 70.062669 | M30: {=INDEX('cumulative-co-emissions1850'!$D$1:$D$260000,MATCH(1, ('cumulative-co-emissions1850'!$C$1:$C$260000=2024)*('cumulative-co-emissions1850'!$B$1:$B$260000=Summary!$B30), 0)) - IFERROR(INDEX('cumulative-co-emissions1850'!$D$1:$D$260000,MATCH(1, ('cumulative-co-emissions1850'!$C$1:$C$260000=1850)*('cumulative-co-emissions1850'!$B$1:$B$260000=Summary!$B30), 0)), 0)} -> 5719013340 | N30: {=INDEX('cumulative-co-emissions1850'!$D$1:$D$260000,MATCH(1, ('cumulative-co-emissions1850'!$C$1:$C$260000=2024)*('cumulative-co-emissions1850'!$B$1:$B$260000=Summary!$B30), 0)) - IFERROR(INDEX('cumulative-co-emissions1850'!$D$1:$D$260000,MATCH(1, ('cumulative-co-emissions1850'!$C$1:$C$260000=1990)*('cumulative-co-emissions1850'!$B$1:$B$260000=Summary!$B30), 0)), 0)} -> 2294945000 | O30: 4706442.1 | P30: 72239.321 | Q30: 9040000 | R30: 788.21006 | S30: 7.9910753 | T30: 450000000000 | U30: 450000000000 | V30: 542000000000 | W30: 50478.333 | X30: 60835 | Y30: =VLOOKUP(B30,gain!$A$2:$AE$193, 31) -> 67.943328 | Z30: =IFERROR(VLOOKUP(B30,EIB!$B$2:$F$177, 2, FALSE), 0.1) -> 0.1 | AA30: =IFERROR(VLOOKUP(B30,EIB!$B$2:$F$177, 4, FALSE), 0.1) -> 0.1 | AB30: =VLOOKUP(B30,'UN Multilaterism Index'!$B$2:$C$194, 2,FALSE) -> 76.7
A31: Sweden | B31: SWE | C31: Northern Europe | D31: 1 | E31: 1 | F31: =IF(G31=1, 1, 0) -> 1 | G31: 1 | H31: 1 | I31: 1 | J31: 1 | K31: 1 | L31: 71.774172 | M31: {=INDEX('cumulative-co-emissions1850'!$D$1:$D$260000,MATCH(1, ('cumulative-co-emissions1850'!$C$1:$C$260000=2024)*('cumulative-co-emissions1850'!$B$1:$B$260000=Summary!$B31), 0)) - IFERROR(INDEX('cumulative-co-emissions1850'!$D$1:$D$260000,MATCH(1, ('cumulative-co-emissions1850'!$C$1:$C$260000=1850)*('cumulative-co-emissions1850'!$B$1:$B$260000=Summary!$B31), 0)), 0)} -> 5133373792 | N31: {=INDEX('cumulative-co-emissions1850'!$D$1:$D$260000,MATCH(1, ('cumulative-co-emissions1850'!$C$1:$C$260000=2024)*('cumulative-co-emissions1850'!$B$1:$B$260000=Summary!$B31), 0)) - IFERROR(INDEX('cumulative-co-emissions1850'!$D$1:$D$260000,MATCH(1, ('cumulative-co-emissions1850'!$C$1:$C$260000=1990)*('cumulative-co-emissions1850'!$B$1:$B$260000=Summary!$B31), 0)), 0)} -> 1702946000 | O31: 3787359.1 | P31: 9531.0437 | Q31: 10500000 | R31: 664.3933 | S31: 0.90771845 | T31: 591000000000 | U31: 591000000000 | V31: 623000000000 | W31: 57373.333 | X31: 60475 | Y31: =VLOOKUP(B31,gain!$A$2:$AE$193, 31) -> 44.350223 | Z31: =IFERROR(VLOOKUP(B31,EIB!$B$2:$F$177, 2, FALSE), 0.1) -> 0.1 | AA31: =IFERROR(VLOOKUP(B31,EIB!$B$2:$F$177, 4, FALSE), 0.1) -> 0.1 | AB31: =VLOOKUP(B31,'UN Multilaterism Index'!$B$2:$C$194, 2,FALSE) -> 68.6
A32: Spain | B32: ESP | C32: Southern Europe | D32: 1 | E32: 1 | F32: =IF(G32=1, 1, 0) -> 1 | G32: 1 | H32: 1 | I32: 1 | J32: 1 | K32: 1 | L32: 61.911989 | M32: {=INDEX('cumulative-co-emissions1850'!$D$1:$D$260000,MATCH(1, ('cumulative-co-emissions1850'!$C$1:$C$260000=2024)*('cumulative-co-emissions1850'!$B$1:$B$260000=Summary!$B32), 0)) - IFERROR(INDEX('cumulative-co-emissions1850'!$D$1:$D$260000,MATCH(1, ('cumulative-co-emissions1850'!$C$1:$C$260000=1850)*('cumulative-co-emissions1850'!$B$1:$B$260000=Summary!$B32), 0)), 0)} -> 15697486328 | N32: {=INDEX('cumulative-co-emissions1850'!$D$1:$D$260000,MATCH(1, ('cumulative-co-emissions1850'!$C$1:$C$260000=2024)*('cumulative-co-emissions1850'!$B$1:$B$260000=Summary!$B32), 0)) - IFERROR(INDEX('cumulative-co-emissions1850'!$D$1:$D$260000,MATCH(1, ('cumulative-co-emissions1850'!$C$1:$C$260000=1990)*('cumulative-co-emissions1850'!$B$1:$B$260000=Summary!$B32), 0)), 0)} -> 9476031400 | O32: 14892364 | P32: 248756.58 | Q32: 47800000 | R32: 413.00722 | S32: 5.2041126 | T32: 1390000000000 | U32: 1390000000000 | V32: 2010000000000 | W32: 29361.667 | X32: 42686.667 | Y32: =VLOOKUP(B32,gain!$A$2:$AE$193, 31) -> 44.869931 | Z32: =IFERROR(VLOOKUP(B32,EIB!$B$2:$F$177, 2, FALSE), 0.1) -> 0.1 | AA32: =IFERROR(VLOOKUP(B32,EIB!$B$2:$F$177, 4, FALSE), 0.1) -> 0.1 | AB32: =VLOOKUP(B32,'UN Multilaterism Index'!$B$2:$C$194, 2,FALSE) -> 69.2
A33: Brunei Darussalam | B33: BRN | C33: South-eastern Asia | D33: 0 | E33: 1 | F33: =IF(G33=1, 1, 0) -> 0 | G33: 0 | H33: 1 | I33: 1 | J33: 1 | K33: 1 | L33: 56.452558 | M33: {=INDEX('cumulative-co-emissions1850'!$D$1:$D$260000,MATCH(1, ('cumulative-co-emissions1850'!$C$1:$C$260000=2024)*('cumulative-co-emissions1850'!$B$1:$B$260000=Summary!$B33), 0)) - IFERROR(INDEX('cumulative-co-emissions1850'!$D$1:$D$260000,MATCH(1, ('cumulative-co-emissions1850'!$C$1:$C$260000=1850)*('cumulative-co-emissions1850'!$B$1:$B$260000=Summary!$B33), 0)), 0)} -> 427762400 | N33: {=INDEX('cumulative-co-emissions1850'!$D$1:$D$260000,MATCH(1, ('cumulative-co-emissions1850'!$C$1:$C$260000=2024)*('cumulative-co-emissions1850'!$B$1:$B$260000=Summary!$B33), 0)) - IFERROR(INDEX('cumulative-co-emissions1850'!$D$1:$D$260000,MATCH(1, ('cumulative-co-emissions1850'!$C$1:$C$260000=1990)*('cumulative-co-emissions1850'!$B$1:$B$260000=Summary!$B33), 0)), 0)} -> 266801870 | O33: 556750.96 | P33: 16635.342 | Q33: 449000 | R33: 1494.9064 | S33: 37.049759 | T33: 13400000000 | U33: 13400000000 | V33: 28800000000 | W33: 30541.667 | X33: 65416.667 | Y33: =VLOOKUP(B33,gain!$A$2:$AE$193, 31) -> 32.881356 | Z33: =IFERROR(VLOOKUP(B33,EIB!$B$2:$F$177, 2, FALSE), 0.1) -> 0.1 | AA33: =IFERROR(VLOOKUP(B33,EIB!$B$2:$F$177, 4, FALSE), 0.1) -> 0.1 | AB33: =VLOOKUP(B33,'UN Multilaterism Index'!$B$2:$C$194, 2,FALSE) -> 71.8
A34: Czechia | B34: CZE | C34: Eastern Europe | D34: 1 | E34: 1 | F34: 1 | G34: 0 | H34: 1 | I34: 1 | J34: 1 | K34: 1 | L34: 64.628962 | M34: {=INDEX('cumulative-co-emissions1850'!$D$1:$D$260000,MATCH(1, ('cumulative-co-emissions1850'!$C$1:$C$260000=2024)*('cumulative-co-emissions1850'!$B$1:$B$260000=Summary!$B34), 0)) - IFERROR(INDEX('cumulative-co-emissions1850'!$D$1:$D$260000,MATCH(1, ('cumulative-co-emissions1850'!$C$1:$C$260000=1850)*('cumulative-co-emissions1850'!$B$1:$B$260000=Summary!$B34), 0)), 0)} -> 12331785000 | N34: {=INDEX('cumulative-co-emissions1850'!$D$1:$D$260000,MATCH(1, ('cumulative-co-emissions1850'!$C$1:$C$260000=2024)*('cumulative-co-emissions1850'!$B$1:$B$260000=Summary!$B34), 0)) - IFERROR(INDEX('cumulative-co-emissions1850'!$D$1:$D$260000,MATCH(1, ('cumulative-co-emissions1850'!$C$1:$C$260000=1990)*('cumulative-co-emissions1850'!$B$1:$B$260000=Summary!$B34), 0)), 0)} -> 3983890700 | O34: 10597397 | P34: 126239.04 | Q34: 10700000 | R34: 1553.5929 | S34: 11.798041 | T34: 236000000000 | U34: 236000000000 | V34: 452000000000 | W34: 22236.667 | X34: 42518.333 | Y34: =VLOOKUP(B34,gain!$A$2:$AE$193, 31) -> 62.893412 | Z34: =IFERROR(VLOOKUP(B34,EIB!$B$2:$F$177, 2, FALSE), 0.1) -> 0.1 | AA34: =IFERROR(VLOOKUP(B34,EIB!$B$2:$F$177, 4, FALSE), 0.1) -> 0.1 | AB34: =VLOOKUP(B34,'UN Multilaterism Index'!$B$2:$C$194, 2,FALSE) -> 66.5
A35: Kuwait | B35: KWT | C35: Western Asia | D35: 0 | E35: 1 | F35: =IF(G35=1, 1, 0) -> 0 | G35: 0 | H35: 1 | I35: 1 | J35: 1 | K35: 1 | L35: 53.955859 | M35: {=INDEX('cumulative-co-emissions1850'!$D$1:$D$260000,MATCH(1, ('cumulative-co-emissions1850'!$C$1:$C$260000=2024)*('cumulative-co-emissions1850'!$B$1:$B$260000=Summary!$B35), 0)) - IFERROR(INDEX('cumulative-co-emissions1850'!$D$1:$D$260000,MATCH(1, ('cumulative-co-emissions1850'!$C$1:$C$260000=1850)*('cumulative-co-emissions1850'!$B$1:$B$260000=Summary!$B35), 0)), 0)} -> 3875923200 | N35: {=INDEX('cumulative-co-emissions1850'!$D$1:$D$260000,MATCH(1, ('cumulative-co-emissions1850'!$C$1:$C$260000=2024)*('cumulative-co-emissions1850'!$B$1:$B$260000=Summary!$B35), 0)) - IFERROR(INDEX('cumulative-co-emissions1850'!$D$1:$D$260000,MATCH(1, ('cumulative-co-emissions1850'!$C$1:$C$260000=1990)*('cumulative-co-emissions1850'!$B$1:$B$260000=Summary!$B35), 0)), 0)} -> 3092921300 | O35: 2896613.9 | P35: 103709.83 | Q35: 4270000 | R35: 797.2153 | S35: 24.288016 | T35: 147000000000 | U35: 147000000000 | V35: 251000000000 | W35: 34135 | X35: 58495 | Y35: =VLOOKUP(B35,gain!$A$2:$AE$193, 31) -> 53.875522 | Z35: =IFERROR(VLOOKUP(B35,EIB!$B$2:$F$177, 2, FALSE), 0.1) -> 1.8 | AA35: =IFERROR(VLOOKUP(B35,EIB!$B$2:$F$177, 4, FALSE), 0.1) -> 1.5 | AB35: =VLOOKUP(B35,'UN Multilaterism Index'!$B$2:$C$194, 2,FALSE) -> 79.5
A36: Finland | B36: FIN | C36: Northern Europe | D36: 1 | E36: 1 | F36: =IF(G36=1, 1, 0) -> 1 | G36: 1 | H36: 1 | I36: 1 | J36: 1 | K36: 1 | L36: 73.68879 | M36: {=INDEX('cumulative-co-emissions1850'!$D$1:$D$260000,MATCH(1, ('cumulative-co-emissions1850'!$C$1:$C$260000=2024)*('cumulative-co-emissions1850'!$B$1:$B$260000=Summary!$B36), 0)) - IFERROR(INDEX('cumulative-co-emissions1850'!$D$1:$D$260000,MATCH(1, ('cumulative-co-emissions1850'!$C$1:$C$260000=1850)*('cumulative-co-emissions1850'!$B$1:$B$260000=Summary!$B36), 0)), 0)} -> 3324778500 | N36: {=INDEX('cumulative-co-emissions1850'!$D$1:$D$260000,MATCH(1, ('cumulative-co-emissions1850'!$C$1:$C$260000=2024)*('cumulative-co-emissions1850'!$B$1:$B$260000=Summary!$B36), 0)) - IFERROR(INDEX('cumulative-co-emissions1850'!$D$1:$D$260000,MATCH(1, ('cumulative-co-emissions1850'!$C$1:$C$260000=1990)*('cumulative-co-emissions1850'!$B$1:$B$260000=Summary!$B36), 0)), 0)} -> 1832526100 | O36: 3174628.1 | P36: 41295.014 | Q36: 5560000 | R36: 875.64406 | S36: 7.4271608 | T36: 278000000000 | U36: 278000000000 | V36: 301000000000 | W36: 50196.667 | X36: 54476.667 | Y36: =VLOOKUP(B36,gain!$A$2:$AE$193, 31) -> 44.869931 | Z36: =IFERROR(VLOOKUP(B36,EIB!$B$2:$F$177, 2, FALSE), 0.1) -> 0.1 | AA36: =IFERROR(VLOOKUP(B36,EIB!$B$2:$F$177, 4, FALSE), 0.1) -> 0.1 | AB36: =VLOOKUP(B36,'UN Multilaterism Index'!$B$2:$C$194, 2,FALSE) -> 67.4
A37: Turkey | B37: TUR | C37: Western Asia | D37: 1 | E37: 1 | F37: 1 | G37: 0 | H37: 1 | I37: 1 | J37: 1 | K37: 0 | L37: 55.846314 | M37: {=INDEX('cumulative-co-emissions1850'!$D$1:$D$260000,MATCH(1, ('cumulative-co-emissions1850'!$C$1:$C$260000=2024)*('cumulative-co-emissions1850'!$B$1:$B$260000=Summary!$B37), 0)) - IFERROR(INDEX('cumulative-co-emissions1850'!$D$1:$D$260000,MATCH(1, ('cumulative-co-emissions1850'!$C$1:$C$260000=1850)*('cumulative-co-emissions1850'!$B$1:$B$260000=Summary!$B37), 0)), 0)} -> 12887552000 | N37: {=INDEX('cumulative-co-emissions1850'!$D$1:$D$260000,MATCH(1, ('cumulative-co-emissions1850'!$C$1:$C$260000=2024)*('cumulative-co-emissions1850'!$B$1:$B$260000=Summary!$B37), 0)) - IFERROR(INDEX('cumulative-co-emissions1850'!$D$1:$D$260000,MATCH(1, ('cumulative-co-emissions1850'!$C$1:$C$260000=1990)*('cumulative-co-emissions1850'!$B$1:$B$260000=Summary!$B37), 0)), 0)} -> 10477029400 | O37: 17001902 | P37: 501708.75 | Q37: 85000000 | R37: 282.24812 | S37: 5.9024559 | T37: 846000000000 | U37: 792000000000 | V37: 2510000000000 | W37: 10225 | X37: 30220 | Y37: =VLOOKUP(B37,gain!$A$2:$AE$193, 31) -> 53.902791 | Z37: =IFERROR(VLOOKUP(B37,EIB!$B$2:$F$177, 2, FALSE), 0.1) -> 0.1 | AA37: =IFERROR(VLOOKUP(B37,EIB!$B$2:$F$177, 4, FALSE), 0.1) -> 0 | AB37: =VLOOKUP(B37,'UN Multilaterism Index'!$B$2:$C$194, 2,FALSE) -> 58.3
A38: Iceland | B38: ISL | C38: Northern Europe | D38: 1 | E38: 1 | F38: =IF(G38=1, 1, 0) -> 1 | G38: 1 | H38: 1 | I38: 1 | J38: 1 | K38: 1 | L38: 70.680574 | M38: {=INDEX('cumulative-co-emissions1850'!$D$1:$D$260000,MATCH(1, ('cumulative-co-emissions1850'!$C$1:$C$260000=2024)*('cumulative-co-emissions1850'!$B$1:$B$260000=Summary!$B38), 0)) - IFERROR(INDEX('cumulative-co-emissions1850'!$D$1:$D$260000,MATCH(1, ('cumulative-co-emissions1850'!$C$1:$C$260000=1850)*('cumulative-co-emissions1850'!$B$1:$B$260000=Summary!$B38), 0)), 0)} -> 171686030 | N38: {=INDEX('cumulative-co-emissions1850'!$D$1:$D$260000,MATCH(1, ('cumulative-co-emissions1850'!$C$1:$C$260000=2024)*('cumulative-co-emissions1850'!$B$1:$B$260000=Summary!$B38), 0)) - IFERROR(INDEX('cumulative-co-emissions1850'!$D$1:$D$260000,MATCH(1, ('cumulative-co-emissions1850'!$C$1:$C$260000=1990)*('cumulative-co-emissions1850'!$B$1:$B$260000=Summary!$B38), 0)), 0)} -> 107406140 | O38: 1043249.7 | P38: 14257.125 | Q38: 382000 | R38: 4299.0134 | S38: 37.322317 | T38: 23900000000 | U38: 23900000000 | V38: 21200000000 | W38: 65823.333 | X38: 58258.333 | Y38: =VLOOKUP(B38,gain!$A$2:$AE$193, 31) -> 64.063138 | Z38: =IFERROR(VLOOKUP(B38,EIB!$B$2:$F$177, 2, FALSE), 0.1) -> 0.1 | AA38: =IFERROR(VLOOKUP(B38,EIB!$B$2:$F$177, 4, FALSE), 0.1) -> 0 | AB38: =VLOOKUP(B38,'UN Multilaterism Index'!$B$2:$C$194, 2,FALSE) -> 69.4
A39: Kazakhstan | B39: KAZ | C39: Central Asia | D39: 0 | E39: 1 | F39: =IF(G39=1, 1, 0) -> 0 | G39: 0 | H39: 1 | I39: 1 | J39: 1 | K39: 0 | L39: 59.439522 | M39: {=INDEX('cumulative-co-emissions1850'!$D$1:$D$260000,MATCH(1, ('cumulative-co-emissions1850'!$C$1:$C$260000=2024)*('cumulative-co-emissions1850'!$B$1:$B$260000=Summary!$B39), 0)) - IFERROR(INDEX('cumulative-co-emissions1850'!$D$1:$D$260000,MATCH(1, ('cumulative-co-emissions1850'!$C$1:$C$260000=1850)*('cumulative-co-emissions1850'!$B$1:$B$260000=Summary!$B39), 0)), 0)} -> 14937427599 | N39: {=INDEX('cumulative-co-emissions1850'!$D$1:$D$260000,MATCH(1, ('cumulative-co-emissions1850'!$C$1:$C$260000=2024)*('cumulative-co-emissions1850'!$B$1:$B$260000=Summary!$B39), 0)) - IFERROR(INDEX('cumulative-co-emissions1850'!$D$1:$D$260000,MATCH(1, ('cumulative-co-emissions1850'!$C$1:$C$260000=1990)*('cumulative-co-emissions1850'!$B$1:$B$260000=Summary!$B39), 0)), 0)} -> 7708144400 | O39: 19870422 | P39: 361776.71 | Q39: 19600000 | R39: 1448.862 | S39: 18.457995 | T39: 163000000000 | U39: 143000000000 | V39: 456000000000 | W39: 8690 | X39: 24361.667 | Y39: =VLOOKUP(B39,gain!$A$2:$AE$193, 31) -> 58.030748 | Z39: =IFERROR(VLOOKUP(B39,EIB!$B$2:$F$177, 2, FALSE), 0.1) -> 0 | AA39: =IFERROR(VLOOKUP(B39,EIB!$B$2:$F$177, 4, FALSE), 0.1) -> 0 | AB39: =VLOOKUP(B39,'UN Multilaterism Index'!$B$2:$C$194, 2,FALSE) -> 76.6
A40: San Marino | B40: SMR | C40: Southern Europe | D40: 0 | E40: 1 | F40: =IF(G40=1, 1, 0) -> 0 | G40: 0 | H40: 1 | I40: 1 | J40: 0 | K40: 1 | M40: {=INDEX('cumulative-co-emissions1850'!$D$1:$D$260000,MATCH(1, ('cumulative-co-emissions1850'!$C$1:$C$260000=2024)*('cumulative-co-emissions1850'!$B$1:$B$260000=Summary!$B40), 0)) - IFERROR(INDEX('cumulative-co-emissions1850'!$D$1:$D$260000,MATCH(1, ('cumulative-co-emissions1850'!$C$1:$C$260000=1850)*('cumulative-co-emissions1850'!$B$1:$B$260000=Summary!$B40), 0)), 0)} -> #N/A | N40: {=INDEX('cumulative-co-emissions1850'!$D$1:$D$260000,MATCH(1, ('cumulative-co-emissions1850'!$C$1:$C$260000=2024)*('cumulative-co-emissions1850'!$B$1:$B$260000=Summary!$B40), 0)) - IFERROR(INDEX('cumulative-co-emissions1850'!$D$1:$D$260000,MATCH(1, ('cumulative-co-emissions1850'!$C$1:$C$260000=1990)*('cumulative-co-emissions1850'!$B$1:$B$260000=Summary!$B40), 0)), 0)} -> #N/A | O40: 10898.137 | P40: 183.39114 | Q40: 33700 | R40: 421.30022 | S40: 5.4418736 | T40: 1460000000 | U40: 1460000000 | V40: 1910000000 | W40: 42990 | X40: 56192 | Y40: =VLOOKUP(B40,gain!$A$2:$AE$193, 31) -> 40.379899 | Z40: =IFERROR(VLOOKUP(B40,EIB!$B$2:$F$177, 2, FALSE), 0.1) -> 0.1 | AA40: =IFERROR(VLOOKUP(B40,EIB!$B$2:$F$177, 4, FALSE), 0.1) -> 0 | AB40: =VLOOKUP(B40,'UN Multilaterism Index'!$B$2:$C$194, 2,FALSE) -> 66.6
A41: Argentina | B41: ARG | C41: Latin America and the Caribbean | D41: 0 | E41: 1 | F41: =IF(G41=1, 1, 0) -> 0 | G41: 0 | H41: 1 | I41: 1 | J41: 1 | K41: 0 | L41: 49.747516 | M41: {=INDEX('cumulative-co-emissions1850'!$D$1:$D$260000,MATCH(1, ('cumulative-co-emissions1850'!$C$1:$C$260000=2024)*('cumulative-co-emissions1850'!$B$1:$B$260000=Summary!$B41), 0)) - IFERROR(INDEX('cumulative-co-emissions1850'!$D$1:$D$260000,MATCH(1, ('cumulative-co-emissions1850'!$C$1:$C$260000=1850)*('cumulative-co-emissions1850'!$B$1:$B$260000=Summary!$B41), 0)), 0)} -> 9151537000 | N41: {=INDEX('cumulative-co-emissions1850'!$D$1:$D$260000,MATCH(1, ('cumulative-co-emissions1850'!$C$1:$C$260000=2024)*('cumulative-co-emissions1850'!$B$1:$B$260000=Summary!$B41), 0)) - IFERROR(INDEX('cumulative-co-emissions1850'!$D$1:$D$260000,MATCH(1, ('cumulative-co-emissions1850'!$C$1:$C$260000=1990)*('cumulative-co-emissions1850'!$B$1:$B$260000=Summary!$B41), 0)), 0)} -> 5493485000 | O41: 19207988 | P41: 398764.71 | Q41: 46200000 | R41: 565.92514 | S41: 8.6312708 | T41: 506000000000 | U41: 474000000000 | V41: 1030000000000 | W41: 11228.333 | X41: 22861.667 | Y41: =VLOOKUP(B41,gain!$A$2:$AE$193, 31) -> 49.747451 | Z41: =IFERROR(VLOOKUP(B41,EIB!$B$2:$F$177, 2, FALSE), 0.1) -> 0.3 | AA41: =IFERROR(VLOOKUP(B41,EIB!$B$2:$F$177, 4, FALSE), 0.1) -> 0.1 | AB41: =VLOOKUP(B41,'UN Multilaterism Index'!$B$2:$C$194, 2,FALSE) -> 88.6
...

Sheet UN Multilaterism Index
A1: Country | B1: ISO Code | C1: Score
A2: Barbados | B2: =VLOOKUP(A2, Summary!$A$2:$B$171, 2, FALSE) -> BRB | C2: 92
A3: Antigua and Barbuda | B3: =VLOOKUP(A3, Summary!$A$2:$B$171, 2, FALSE) -> ATG | C3: 91.1
A4: Uruguay | B4: =VLOOKUP(A4, Summary!$A$2:$B$171, 2, FALSE) -> URY | C4: 90.7
A5: Mauritius | B5: =VLOOKUP(A5, Summary!$A$2:$B$171, 2, FALSE) -> MUS | C5: 89.7
A6: Maldives | B6: =VLOOKUP(A6, Summary!$A$2:$B$171, 2, FALSE) -> MDV | C6: 88.8
A7: Jamaica | B7: =VLOOKUP(A7, Summary!$A$2:$B$171, 2, FALSE) -> JAM | C7: 88.7
A8: Costa Rica | B8: =VLOOKUP(A8, Summary!$A$2:$B$171, 2, FALSE) -> CRI | C8: 88.6
A9: Argentina | B9: =VLOOKUP(A9, Summary!$A$2:$B$171, 2, FALSE) -> ARG | C9: 88.6
A10: Fiji | B10: =VLOOKUP(A10, Summary!$A$2:$B$171, 2, FALSE) -> FJI | C10: 88.3
A11: Chile | B11: =VLOOKUP(A11, Summary!$A$2:$B$171, 2, FALSE) -> CHL | C11: 87.2
A12: Belize | B12: =VLOOKUP(A12, Summary!$A$2:$B$171, 2, FALSE) -> BLZ | C12: 86.8
A13: Paraguay | B13: =VLOOKUP(A13, Summary!$A$2:$B$171, 2, FALSE) -> PRY | C13: 86.7
... A26: Malaysia | B26: =VLOOKUP(A26, Summary!$A$2:$B$171, 2, FALSE) -> MYS | C26: 83.1
A27: Madagascar | B27: MDG | C27: 82.8
A28: Philippines | B28: =VLOOKUP(A28, Summary!$A$2:$B$171, 2, FALSE) -> PHL | C28: 82.7
A29: Botswana | B29: =VLOOKUP(A29, Summary!$A$2:$B$171, 2, FALSE) -> BWA | C29: 82.6
A30: St. Lucia | B30: =VLOOKUP(A30, Summary!$A$2:$B$171, 2, FALSE) -> LCA | C30: 82.5
A31: Dominican Republic | B31: =VLOOKUP(A31, Summary!$A$2:$B$171, 2, FALSE) -> DOM | C31: 82.5
A32: El Salvador | B32: =VLOOKUP(A32, Summary!$A$2:$B$171, 2, FALSE) -> SLV | C32: 82.3
A33: Suriname | B33: =VLOOKUP(A33, Summary!$A$2:$B$171, 2, FALSE) -> SUR | C33: 81.5
A34: Namibia | B34: NAM | C34: 81.3
A35: Cote d‚ÄôIvoire | B35: CIV | C35: 81.2
A36: Ghana | B36: =VLOOKUP(A36, Summary!$A$2:$B$171, 2, FALSE) -> GHA | C36: 80.7
A37: Bolivia | B37: =VLOOKUP(A37, Summary!$A$2:$B$171, 2, FALSE) -> BOL | C37: 80.6
A38: Jordan | B38: =VLOOKUP(A38, Summary!$A$2:$B$171, 2, FALSE) -> JOR | C38: 80.2
A39: Bangladesh | B39: =VLOOKUP(A39, Summary!$A$2:$B$171, 2, FALSE) -> BGD | C39: 80.2
A40: Vietnam | B40: =VLOOKUP(A40, Summary!$A$2:$B$171, 2, FALSE) -> VNM | C40: 80.1
A41: Kuwait | B41: =VLOOKUP(A41, Summary!$A$2:$B$171, 2, FALSE) -> KWT | C41: 79.5
A42: Honduras | B42: =VLOOKUP(A42, Summary!$A$2:$B$171, 2, FALSE) -> HND | C42: 79.2
A43: Nicaragua | B43: =VLOOKUP(A43, Summary!$A$2:$B$171, 2, FALSE) -> NIC | C43: 79
A44: Malawi | B44: =VLOOKUP(A44, Summary!$A$2:$B$171, 2, FALSE) -> MWI | C44: 78.6
A45: Malta | B45: =VLOOKUP(A45, Summary!$A$2:$B$171, 2, FALSE) -> MLT | C45: 78.4
A46: Seychelles | B46: =VLOOKUP(A46, Summary!$A$2:$B$171, 2, FALSE) -> SYC | C46: 78.2
A47: Lesotho | B47: =VLOOKUP(A47, Summary!$A$2:$B$171, 2, FALSE) -> LSO | C47: 78.1
... A55: South Africa | B55: =VLOOKUP(A55, Summary!$A$2:$B$171, 2, FALSE) -> ZAF | C55: 77
A56: Gabon | B56: GAB | C56: 77
A57: Sri Lanka | B57: =VLOOKUP(A57, Summary!$A$2:$B$171, 2, FALSE) -> LKA | C57: 77
A58: Guyana | B58: GUY | C58: 76.7
A59: Austria | B59: =VLOOKUP(A59, Summary!$A$2:$B$171, 2, FALSE) -> AUT | C59: 76.7
...

Sheet EIB
A1: Country | C1: Physical risk | D1: Adaptation capacity | E1: Physical risk inc. adaptation capacity | F1: Transition risk
A2: EU Countries (average) | B2: =VLOOKUP(A2,Summary!$A$2:$B$171, 2,FALSE) -> #N/A | C2: 0.1 | D2: 0.8 | E2: 0 | F2: 0.9
A3: Afghanistan | B3: =VLOOKUP(A3,Summary!$A$2:$B$171, 2,FALSE) -> AFG | C3: 1.1 | D3: 0.3 | E3: 1
A4: Albania | B4: =VLOOKUP(A4,Summary!$A$2:$B$171, 2,FALSE) -> ALB | C4: 0.2 | D4: 0.5 | E4: 0 | F4: 0.4
A5: Algeria | B5: =VLOOKUP(A5,Summary!$A$2:$B$171, 2,FALSE) -> DZA | C5: 1.1 | D5: 0.5 | E5: 0.9 | F5: 1.3
A6: Andorra | B6: AND | C6: 0.1 | D6: 0.6 | E6: 0
A7: Angola | B7: =VLOOKUP(A7,Summary!$A$2:$B$171, 2,FALSE) -> AGO | C7: 0.7 | D7: 0.4 | E7: 0.6 | F7: 0.8
A8: Anguilla | B8: ANG | C8: 2.3 | D8: 0.5 | E8: 2.2
A9: Antigua and Barbuda | B9: =VLOOKUP(A9,Summary!$A$2:$B$171, 2,FALSE) -> ATG | C9: 3.2 | D9: 0.5 | E9: 3 | F9: 1.7
A10: Argentina | B10: =VLOOKUP(A10,Summary!$A$2:$B$171, 2,FALSE) -> ARG | C10: 0.3 | D10: 0.4 | E10: 0.1 | F10: 1
A11: Armenia | B11: =VLOOKUP(A11,Summary!$A$2:$B$171, 2,FALSE) -> ARM | C11: 0.1 | D11: 0.5 | E11: 0 | F11: 1
A12: Aruba | B12: ARU | C12: 2.2 | D12: 0.6 | E12: 1.9 | F12: 1.8
A13: Australia | B13: =VLOOKUP(A13,Summary!$A$2:$B$171, 2,FALSE) -> AUS | C13: 0.5 | D13: 0.9 | E13: 0.2 | F13: 1.7
A14: Azerbaijan | B14: =VLOOKUP(A14,Summary!$A$2:$B$171, 2,FALSE) -> AZE | C14: 0.1 | D14: 0.5 | E14: 0 | F14: 1.1
A15: Bahamas | B15: BHS | C15: 3.5 | D15: 0.5 | E15: 3.4 | F15: 1.5
A16: Bahrain | B16: =VLOOKUP(A16,Summary!$A$2:$B$171, 2,FALSE) -> BHR | C16: 1.3 | D16: 0.5 | E16: 1.1 | F16: 2.2
A17: Bangladesh | B17: =VLOOKUP(A17,Summary!$A$2:$B$171, 2,FALSE) -> BGD | C17: 1.1 | D17: 0.4 | E17: 1 | F17: 0.8
A18: Barbados | B18: =VLOOKUP(A18,Summary!$A$2:$B$171, 2,FALSE) -> BRB | C18: 2.3 | D18: 0.5 | E18: 2.1 | F18: 0.8
A19: Belarus | B19: =VLOOKUP(A19,Summary!$A$2:$B$171, 2,FALSE) -> BLR | C19: 0.1 | D19: 0.6 | E19: 0 | F19: 1.3
A20: Belize | B20: =VLOOKUP(A20,Summary!$A$2:$B$171, 2,FALSE) -> BLZ | C20: 1.4 | D20: 0.4 | E20: 1.3 | F20: 1
A21: Benin | B21: =VLOOKUP(A21,Summary!$A$2:$B$171, 2,FALSE) -> BEN | C21: 1.4 | D21: 0.4 | E21: 1.3 | F21: 0.7
A22: Bhutan | B22: =VLOOKUP(A22,Summary!$A$2:$B$171, 2,FALSE) -> BTN | C22: 0.8 | D22: 0.5 | E22: 0.6 | F22: 1.2
A23: Bolivia | B23: =VLOOKUP(A23,Summary!$A$2:$B$171, 2,FALSE) -> BOL | C23: 0.6 | D23: 0.4 | E23: 0.5 | F23: 1.1
A24: Bosnia and Herzegovina | B24: =VLOOKUP(A24,Summary!$A$2:$B$171, 2,FALSE) -> BIH | C24: 0.8 | D24: 0.5 | E24: 0.6 | F24: 1.8
A25: Botswana | B25: =VLOOKUP(A25,Summary!$A$2:$B$171, 2,FALSE) -> BWA | C25: 0.4 | D25: 0.6 | E25: 0.2 | F25: 1.1
